try:
    print(x)
except:
    print("An exception occured")
finally:
    print("The try-except is finally finished")